plaid.exceptions.ApiTypeError: Invalid type for variable '0'. Required value type is Products and passed type was str at ['products'][0]
Traceback:
File "/home/runner/workspace/.pythonlibs/lib/python3.11/site-packages/streamlit/runtime/scriptrunner/exec_code.py", line 121, in exec_func_with_error_handling
    result = func()
             ^^^^^^
File "/home/runner/workspace/.pythonlibs/lib/python3.11/site-packages/streamlit/runtime/scriptrunner/script_runner.py", line 591, in code_to_exec
    exec(code, module.__dict__)
File "/home/runner/workspace/main.py", line 91, in <module>
    link_token = data_manager.create_link_token()
                 ^^^^^^^^^^^^^^^^^^^^^^^^^^^^^^^^
File "/home/runner/workspace/utils/data_manager.py", line 73, in create_link_token
    return self.plaid_client.create_link_token(user_id)
           ^^^^^^^^^^^^^^^^^^^^^^^^^^^^^^^^^^^^^^^^^^^^
File "/home/runner/workspace/utils/plaid_client.py", line 29, in create_link_token
    request = LinkTokenCreateRequest(
              ^^^^^^^^^^^^^^^^^^^^^^^
File "/home/runner/workspace/.pythonlibs/lib/python3.11/site-packages/plaid/model_utils.py", line 48, in wrapped_init
    return fn(_self, *args, **kwargs)
           ^^^^^^^^^^^^^^^^^^^^^^^^^^
File "/home/runner/workspace/.pythonlibs/lib/python3.11/site-packages/plaid/model/link_token_create_request.py", line 520, in __init__
    setattr(self, var_name, var_value)
File "/home/runner/workspace/.pythonlibs/lib/python3.11/site-packages/plaid/model_utils.py", line 189, in __setattr__
    self[attr] = value
    ~~~~^^^^^^
File "/home/runner/workspace/.pythonlibs/lib/python3.11/site-packages/plaid/model_utils.py", line 510, in __setitem__
    self.set_attribute(name, value)
File "/home/runner/workspace/.pythonlibs/lib/python3.11/site-packages/plaid/model_utils.py", line 161, in set_attribute
    value = validate_and_convert_types(
            ^^^^^^^^^^^^^^^^^^^^^^^^^^^
File "/home/runner/workspace/.pythonlibs/lib/python3.11/site-packages/plaid/model_utils.py", line 1594, in validate_and_convert_types
    input_value[index] = validate_and_convert_types(
                         ^^^^^^^^^^^^^^^^^^^^^^^^^^^
File "/home/runner/workspace/.pythonlibs/lib/python3.11/site-packages/plaid/model_utils.py", line 1556, in validate_and_convert_types
    raise get_type_error(input_value, path_to_item, valid_classes,